Workbook
Name All_India_Index_Upto_April23__1: 'MAIN DATA'!$A$1:$AA$373

Sheet MAIN DATA
A1: Sector | B1: Year | C1: Month | D1: Cereals and products | E1: Meat and fish | F1: Egg | G1: Milk and products | H1: Oils and fats | I1: Fruits | J1: Vegetables | K1: Pulses and products | L1: Sugar and Confectionery | M1: Spices | N1: Non-alcoholic beverages | O1: Prepared meals, snacks, sweets etc. | P1: Pan, tobacco and intoxicants | Q1: Clothing | R1: Footwear | S1: HOUSING | T1: Fuel and light | U1: Household goods and services | V1: Health | W1: Transport and communication | X1: Recreation and amusement | Y1: Education | Z1: Personal care and effects | AA1: General index | AB1: FOOD AND BEVERAGES | AC1: HOUSING | AD1: FUEL AND LIGHT | AE1: CLOTHING AND FOOTWEAR | AF1: MISCELLANEOUS | AG1: TOTAL EQUAL BASKET
A2: Rural | B2: 2013 | C2: January | D2: 107.5 | E2: 106.3 | F2: 108.1 | G2: 104.9 | H2: 106.1 | I2: 103.9 | J2: 101.9 | K2: 106.1 | L2: 106.8 | M2: 103.1 | N2: 104.8 | O2: 106.7 | P2: 105.1 | Q2: 106.5 | R2: 105.8 | T2: 105.5 | U2: 104.8 | V2: 104 | W2: 103.3 | X2: 103.4 | Y2: 103.8 | Z2: 104.7 | AA2: 105.1 | AB2: =SUM(D2:O2) -> 1266.2 | AD2: 105.5 | AE2: =SUM(Q2:R2) -> 212.3 | AF2: =SUM(U2:Z2,P2) -> 729.1 | AG2: =SUM(AB2:AF2) -> 2313.1
A3: Urban | B3: 2013 | C3: January | D3: 110.5 | E3: 109.1 | F3: 113 | G3: 103.6 | H3: 103.4 | I3: 102.3 | J3: 102.9 | K3: 105.8 | L3: 105.1 | M3: 101.8 | N3: 105.1 | O3: 107.9 | P3: 105.2 | Q3: 105.9 | R3: 105 | S3: 100.3 | T3: 105.4 | U3: 104.8 | V3: 104.1 | W3: 103.2 | X3: 102.9 | Y3: 103.5 | Z3: 104.3 | AA3: 104 | AB3: =SUM(D3:O3) -> 1270.5 | AC3: 100.3 | AD3: 105.4 | AE3: =SUM(Q3:R3) -> 210.9 | AF3: =SUM(U3:Z3,P3) -> 728 | AG3: =SUM(AB3:AF3) -> 2415.1
A4: Rural+Urban | B4: 2013 | C4: January | D4: 108.4 | E4: 107.3 | F4: 110 | G4: 104.4 | H4: 105.1 | I4: 103.2 | J4: 102.2 | K4: 106 | L4: 106.2 | M4: 102.7 | N4: 104.9 | O4: 107.3 | P4: 105.1 | Q4: 106.3 | R4: 105.5 | S4: 100.3 | T4: 105.5 | U4: 104.8 | V4: 104 | W4: 103.2 | X4: 103.1 | Y4: 103.6 | Z4: 104.5 | AA4: 104.6 | AB4: =SUM(D4:O4) -> 1267.7 | AC4: 100.3 | AD4: 105.5 | AE4: =SUM(Q4:R4) -> 211.8 | AF4: =SUM(U4:Z4,P4) -> 728.3 | AG4: =SUM(AB4:AF4) -> 2413.6
A5: Rural | B5: 2013 | C5: February | D5: 109.2 | E5: 108.7 | F5: 110.2 | G5: 105.4 | H5: 106.7 | I5: 104 | J5: 102.4 | K5: 105.9 | L5: 105.7 | M5: 103.1 | N5: 105.1 | O5: 107.7 | P5: 105.6 | Q5: 107.1 | R5: 106.3 | T5: 106.2 | U5: 105.2 | V5: 104.4 | W5: 103.9 | X5: 104 | Y5: 104.1 | Z5: 104.6 | AA5: 105.8 | AB5: =SUM(D5:O5) -> 1274.1 | AD5: 106.2 | AE5: =SUM(Q5:R5) -> 213.4 | AF5: =SUM(U5:Z5,P5) -> 731.8 | AG5: =SUM(AB5:AF5) -> 2325.5
A6: Urban | B6: 2013 | C6: February | D6: 112.9 | E6: 112.9 | F6: 116.9 | G6: 104 | H6: 103.5 | I6: 103.1 | J6: 104.9 | K6: 104.1 | L6: 103.8 | M6: 102.3 | N6: 106 | O6: 109 | P6: 106 | Q6: 106.6 | R6: 105.5 | S6: 100.4 | T6: 105.7 | U6: 105.2 | V6: 104.7 | W6: 104.4 | X6: 103.3 | Y6: 103.7 | Z6: 104.3 | AA6: 104.7 | AB6: =SUM(D6:O6) -> 1283.4 | AC6: 100.4 | AD6: 105.7 | AE6: =SUM(Q6:R6) -> 212.1 | AF6: =SUM(U6:Z6,P6) -> 731.6 | AG6: =SUM(AB6:AF6) -> 2433.2
A7: Rural+Urban | B7: 2013 | C7: February | D7: 110.4 | E7: 110.2 | F7: 112.8 | G7: 104.9 | H7: 105.5 | I7: 103.6 | J7: 103.2 | K7: 105.3 | L7: 105.1 | M7: 102.8 | N7: 105.5 | O7: 108.3 | P7: 105.7 | Q7: 106.9 | R7: 106 | S7: 100.4 | T7: 106 | U7: 105.2 | V7: 104.5 | W7: 104.2 | X7: 103.6 | Y7: 103.9 | Z7: 104.5 | AA7: 105.3 | AB7: =SUM(D7:O7) -> 1277.6 | AC7: 100.4 | AD7: 106 | AE7: =SUM(Q7:R7) -> 212.9 | AF7: =SUM(U7:Z7,P7) -> 731.6 | AG7: =SUM(AB7:AF7) -> 2428.5
A8: Rural | B8: 2013 | C8: March | D8: 110.2 | E8: 108.8 | F8: 109.9 | G8: 105.6 | H8: 106.2 | I8: 105.7 | J8: 101.4 | K8: 105.7 | L8: 105 | M8: 103.3 | N8: 105.6 | O8: 108.2 | P8: 106.5 | Q8: 107.6 | R8: 106.8 | T8: 106.1 | U8: 105.6 | V8: 104.7 | W8: 104.6 | X8: 104 | Y8: 104.3 | Z8: 104.3 | AA8: 106 | AB8: =SUM(D8:O8) -> 1275.6 | AD8: 106.1 | AE8: =SUM(Q8:R8) -> 214.4 | AF8: =SUM(U8:Z8,P8) -> 734 | AG8: =SUM(AB8:AF8) -> 2330.1
A9: Urban | B9: 2013 | C9: March | D9: 113.9 | E9: 111.4 | F9: 113.2 | G9: 104.3 | H9: 102.7 | I9: 104.9 | J9: 103.8 | K9: 103.5 | L9: 102.6 | M9: 102.4 | N9: 107 | O9: 109.8 | P9: 106.8 | Q9: 107.2 | R9: 106 | S9: 100.4 | T9: 106 | U9: 105.7 | V9: 105.2 | W9: 105.5 | X9: 103.5 | Y9: 103.8 | Z9: 104.2 | AA9: 105 | AB9: =SUM(D9:O9) -> 1279.5 | AC9: 100.4 | AD9: 106 | AE9: =SUM(Q9:R9) -> 213.2 | AF9: =SUM(U9:Z9,P9) -> 734.7 | AG9: =SUM(AB9:AF9) -> 2433.8
A10: Rural+Urban | B10: 2013 | C10: March | D10: 111.4 | E10: 109.7 | F10: 111.2 | G10: 105.1 | H10: 104.9 | I10: 105.3 | J10: 102.2 | K10: 105 | L10: 104.2 | M10: 103 | N10: 106.2 | O10: 108.9 | P10: 106.6 | Q10: 107.4 | R10: 106.5 | S10: 100.4 | T10: 106.1 | U10: 105.6 | V10: 104.9 | W10: 105.1 | X10: 103.7 | Y10: 104 | Z10: 104.3 | AA10: 105.5 | AB10: =SUM(D10:O10) -> 1277.1 | AC10: 100.4 | AD10: 106.1 | AE10: =SUM(Q10:R10) -> 213.9 | AF10: =SUM(U10:Z10,P10) -> 734.2 | AG10: =SUM(AB10:AF10) -> 2431.7
A11: Rural | B11: 2013 | C11: April | D11: 110.2 | E11: 109.5 | F11: 106.9 | G11: 106.3 | H11: 105.7 | I11: 108.3 | J11: 103.4 | K11: 105.7 | L11: 104.2 | M11: 103.2 | N11: 106.5 | O11: 108.8 | P11: 107.1 | Q11: 108.1 | R11: 107.4 | T11: 106.5 | U11: 106.1 | V11: 105.1 | W11: 104.4 | X11: 104.5 | Y11: 104.8 | Z11: 102.7 | AA11: 106.4 | AB11: =SUM(D11:O11) -> 1278.7 | AD11: 106.5 | AE11: =SUM(Q11:R11) -> 215.5 | AF11: =SUM(U11:Z11,P11) -> 734.7 | AG11: =SUM(AB11:AF11) -> 2335.4
A12: Urban | B12: 2013 | C12: April | D12: 114.6 | E12: 113.4 | F12: 106 | G12: 104.7 | H12: 102.1 | I12: 109.5 | J12: 109.7 | K12: 104.6 | L12: 102 | M12: 103.5 | N12: 108.2 | O12: 110.6 | P12: 108.5 | Q12: 107.9 | R12: 106.4 | S12: 100.5 | T12: 106.4 | U12: 106.5 | V12: 105.7 | W12: 105 | X12: 104 | Y12: 105.2 | Z12: 103.2 | AA12: 105.7 | AB12: =SUM(D12:O12) -> 1288.9 | AC12: 100.5 | AD12: 106.4 | AE12: =SUM(Q12:R12) -> 214.3 | AF12: =SUM(U12:Z12,P12) -> 738.1 | AG12: =SUM(AB12:AF12) -> 2448.2
A13: Rural+Urban | B13: 2013 | C13: April | D13: 111.6 | E13: 110.9 | F13: 106.6 | G13: 105.7 | H13: 104.4 | I13: 108.9 | J13: 105.5 | K13: 105.3 | L13: 103.5 | M13: 103.3 | N13: 107.2 | O13: 109.6 | P13: 107.5 | Q13: 108 | R13: 107 | S13: 100.5 | T13: 106.5 | U13: 106.3 | V13: 105.3 | W13: 104.7 | X13: 104.2 | Y13: 105 | Z13: 102.9 | AA13: 106.1 | AB13: =SUM(D13:O13) -> 1282.5 | AC13: 100.5 | AD13: 106.5 | AE13: =SUM(Q13:R13) -> 215 | AF13: =SUM(U13:Z13,P13) -> 735.9 | AG13: =SUM(AB13:AF13) -> 2440.4
A14: Rural | B14: 2013 | C14: May | D14: 110.9 | E14: 109.8 | F14: 105.9 | G14: 107.5 | H14: 105.3 | I14: 108.1 | J14: 107.3 | K14: 106.1 | L14: 103.7 | M14: 104 | N14: 107.4 | O14: 109.9 | P14: 108.1 | Q14: 108.8 | R14: 107.9 | T14: 107.5 | U14: 106.8 | V14: 105.7 | W14: 104.1 | X14: 105 | Y14: 105.5 | Z14: 102.1 | AA14: 107.2 | AB14: =SUM(D14:O14) -> 1285.9 | AD14: 107.5 | AE14: =SUM(Q14:R14) -> 216.7 | AF14: =SUM(U14:Z14,P14) -> 737.3 | AG14: =SUM(AB14:AF14) -> 2347.4
A15: Urban | B15: 2013 | C15: May | D15: 115.4 | E15: 114.2 | F15: 102.7 | G15: 105.5 | H15: 101.5 | I15: 110.6 | J15: 123.7 | K15: 105.2 | L15: 101.9 | M15: 105 | N15: 109.1 | O15: 111.3 | P15: 109.8 | Q15: 108.5 | R15: 106.7 | S15: 100.5 | T15: 107.2 | U15: 107.1 | V15: 106.2 | W15: 103.9 | X15: 104.6 | Y15: 105.7 | Z15: 102.6 | AA15: 106.6 | AB15: =SUM(D15:O15) -> 1306.1 | AC15: 100.5 | AD15: 107.2 | AE15: =SUM(Q15:R15) -> 215.2 | AF15: =SUM(U15:Z15,P15) -> 739.9 | AG15: =SUM(AB15:AF15) -> 2468.9
A16: Rural+Urban | B16: 2013 | C16: May | D16: 112.3 | E16: 111.3 | F16: 104.7 | G16: 106.8 | H16: 103.9 | I16: 109.3 | J16: 112.9 | K16: 105.8 | L16: 103.1 | M16: 104.3 | N16: 108.1 | O16: 110.5 | P16: 108.6 | Q16: 108.7 | R16: 107.4 | S16: 100.5 | T16: 107.4 | U16: 106.9 | V16: 105.9 | W16: 104 | X16: 104.8 | Y16: 105.6 | Z16: 102.3 | AA16: 106.9 | AB16: =SUM(D16:O16) -> 1293 | AC16: 100.5 | AD16: 107.4 | AE16: =SUM(Q16:R16) -> 216.1 | AF16: =SUM(U16:Z16,P16) -> 738.1 | AG16: =SUM(AB16:AF16) -> 2455.1
A17: Rural | B17: 2013 | C17: June | D17: 112.3 | E17: 112.1 | F17: 108.1 | G17: 108.3 | H17: 105.9 | I17: 109.2 | J17: 118 | K17: 106.8 | L17: 104.1 | M17: 105.4 | N17: 108.2 | O17: 111 | P17: 109 | Q17: 109.7 | R17: 108.8 | T17: 108.5 | U17: 107.5 | V17: 106.3 | W17: 105 | X17: 105.6 | Y17: 106.5 | Z17: 102.5 | AA17: 108.9 | AB17: =SUM(D17:O17) -> 1309.4 | AD17: 108.5 | AE17: =SUM(Q17:R17) -> 218.5 | AF17: =SUM(U17:Z17,P17) -> 742.4 | AG17: =SUM(AB17:AF17) -> 2378.8
A18: Urban | B18: 2013 | C18: June | D18: 117 | E18: 120.1 | F18: 112.5 | G18: 107.3 | H18: 101.3 | I18: 112.4 | J18: 143.6 | K18: 105.4 | L18: 101.4 | M18: 106.4 | N18: 110 | O18: 112.2 | P18: 110.9 | Q18: 109.2 | R18: 107.2 | S18: 106.6 | T18: 108 | U18: 107.7 | V18: 106.5 | W18: 105.2 | X18: 105.2 | Y18: 108.1 | Z18: 103.3 | AA18: 109.7 | AB18: =SUM(D18:O18) -> 1349.6 | AC18: 106.6 | AD18: 108 | AE18: =SUM(Q18:R18) -> 216.4 | AF18: =SUM(U18:Z18,P18) -> 746.9 | AG18: =SUM(AB18:AF18) -> 2527.5
A19: Rural+Urban | B19: 2013 | C19: June | D19: 113.8 | E19: 114.9 | F19: 109.8 | G19: 107.9 | H19: 104.2 | I19: 110.7 | J19: 126.7 | K19: 106.3 | L19: 103.2 | M19: 105.7 | N19: 109 | O19: 111.6 | P19: 109.5 | Q19: 109.5 | R19: 108.1 | S19: 106.6 | T19: 108.3 | U19: 107.6 | V19: 106.4 | W19: 105.1 | X19: 105.4 | Y19: 107.4 | Z19: 102.8 | AA19: 109.3 | AB19: =SUM(D19:O19) -> 1323.8 | AC19: 106.6 | AD19: 108.3 | AE19: =SUM(Q19:R19) -> 217.6 | AF19: =SUM(U19:Z19,P19) -> 744.2 | AG19: =SUM(AB19:AF19) -> 2500.5
A20: Rural | B20: 2013 | C20: July | D20: 113.4 | E20: 114.9 | F20: 110.5 | G20: 109.3 | H20: 106.2 | I20: 110.3 | J20: 129.2 | K20: 107.1 | L20: 104.3 | M20: 106.4 | N20: 109.1 | O20: 112.1 | P20: 109.8 | Q20: 110.5 | R20: 109.5 | T20: 109.5 | U20: 108.3 | V20: 106.9 | W20: 106.8 | X20: 106.4 | Y20: 107.8 | Z20: 102.5 | AA20: 110.7 | AB20: =SUM(D20:O20) -> 1332.8 | AD20: 109.5 | AE20: =SUM(Q20:R20) -> 220 | AF20: =SUM(U20:Z20,P20) -> 748.5 | AG20: =SUM(AB20:AF20) -> 2410.8
A21: Urban | B21: 2013 | C21: July | D21: 117.8 | E21: 119.2 | F21: 114 | G21: 108.3 | H21: 101.1 | I21: 113.2 | J21: 160.9 | K21: 105.1 | L21: 101.3 | M21: 107.5 | N21: 110.4 | O21: 113.1 | P21: 111.7 | Q21: 109.8 | R21: 107.8 | S21: 107.7 | T21: 108.6 | U21: 108.1 | V21: 107.1 | W21: 107.3 | X21: 105.9 | Y21: 110.1 | Z21: 103.2 | AA21: 111.4 | AB21: =SUM(D21:O21) -> 1371.9 | AC21: 107.7 | AD21: 108.6 | AE21: =SUM(Q21:R21) -> 217.6 | AF21: =SUM(U21:Z21,P21) -> 753.4 | AG21: =SUM(AB21:AF21) -> 2559.2
A22: Rural+Urban | B22: 2013 | C22: July | D22: 114.8 | E22: 116.4 | F22: 111.9 | G22: 108.9 | H22: 104.3 | I22: 111.7 | J22: 140 | K22: 106.4 | L22: 103.3 | M22: 106.8 | N22: 109.6 | O22: 112.6 | P22: 110.3 | Q22: 110.2 | R22: 108.8 | S22: 107.7 | T22: 109.2 | U22: 108.2 | V22: 107 | W22: 107.1 | X22: 106.1 | Y22: 109.1 | Z22: 102.8 | AA22: 111 | AB22: =SUM(D22:O22) -> 1346.7 | AC22: 107.7 | AD22: 109.2 | AE22: =SUM(Q22:R22) -> 219 | AF22: =SUM(U22:Z22,P22) -> 750.6 | AG22: =SUM(AB22:AF22) -> 2533.2
A23: Rural | B23: 2013 | C23: August | D23: 114.3 | E23: 115.4 | F23: 111.1 | G23: 110 | H23: 106.4 | I23: 110.8 | J23: 138.9 | K23: 107.4 | L23: 104.1 | M23: 106.9 | N23: 109.7 | O23: 112.6 | P23: 110.7 | Q23: 111.3 | R23: 110.2 | T23: 109.9 | U23: 108.7 | V23: 107.5 | W23: 107.8 | X23: 106.8 | Y23: 108.7 | Z23: 105 | AA23: 112.1 | AB23: =SUM(D23:O23) -> 1347.6 | AD23: 109.9 | AE23: =SUM(Q23:R23) -> 221.5 | AF23: =SUM(U23:Z23,P23) -> 755.2 | AG23: =SUM(AB23:AF23) -> 2434.2
A24: Urban | B24: 2013 | C24: August | D24: 118.3 | E24: 120.4 | F24: 112.7 | G24: 108.9 | H24: 101.1 | I24: 108.7 | J24: 177 | K24: 104.7 | L24: 101 | M24: 108.5 | N24: 110.9 | O24: 114.3 | P24: 112.4 | Q24: 110.6 | R24: 108.3 | S24: 108.9 | T24: 109.3 | U24: 108.7 | V24: 107.6 | W24: 108.1 | X24: 106.5 | Y24: 110.8 | Z24: 106 | AA24: 112.7 | AB24: =SUM(D24:O24) -> 1386.5 | AC24: 108.9 | AD24: 109.3 | AE24: =SUM(Q24:R24) -> 218.9 | AF24: =SUM(U24:Z24,P24) -> 760.1 | AG24: =SUM(AB24:AF24) -> 2583.7
A25: Rural+Urban | B25: 2013 | C25: August | D25: 115.6 | E25: 117.2 | F25: 111.7 | G25: 109.6 | H25: 104.5 | I25: 109.8 | J25: 151.8 | K25: 106.5 | L25: 103.1 | M25: 107.4 | N25: 110.2 | O25: 113.4 | P25: 111.2 | Q25: 111 | R25: 109.4 | S25: 108.9 | T25: 109.7 | U25: 108.7 | V25: 107.5 | W25: 108 | X25: 106.6 | Y25: 109.9 | Z25: 105.4 | AA25: 112.4 | AB25: =SUM(D25:O25) -> 1360.8 | AC25: 108.9 | AD25: 109.7 | AE25: =SUM(Q25:R25) -> 220.4 | AF25: =SUM(U25:Z25,P25) -> 757.3 | AG25: =SUM(AB25:AF25) -> 2557.1
A26: Rural | B26: 2013 | C26: September | D26: 115.4 | E26: 115.7 | F26: 111.7 | G26: 111 | H26: 107.4 | I26: 110.9 | J26: 154 | K26: 108.1 | L26: 104.2 | M26: 107.9 | N26: 110.4 | O26: 114 | P26: 111.7 | Q26: 112.7 | R26: 111.4 | T26: 111.1 | U26: 109.6 | V26: 108.3 | W26: 109.3 | X26: 107.7 | Y26: 109.8 | Z26: 106.7 | AA26: 114.2 | AB26: =SUM(D26:O26) -> 1370.7 | AD26: 111.1 | AE26: =SUM(Q26:R26) -> 224.1 | AF26: =SUM(U26:Z26,P26) -> 763.1 | AG26: =SUM(AB26:AF26) -> 2469
A27: Urban | B27: 2013 | C27: September | D27: 118.6 | E27: 119.1 | F27: 113.2 | G27: 109.6 | H27: 101.7 | I27: 103.2 | J27: 174.3 | K27: 105.1 | L27: 100.8 | M27: 109.1 | N27: 111.1 | O27: 115.4 | P27: 112.9 | Q27: 111.4 | R27: 109 | S27: 109.7 | T27: 109.5 | U27: 109.6 | V27: 107.9 | W27: 110.4 | X27: 107.4 | Y27: 111.2 | Z27: 106.9 | AA27: 113.2 | AB27: =SUM(D27:O27) -> 1381.2 | AC27: 109.7 | AD27: 109.5 | AE27: =SUM(Q27:R27) -> 220.4 | AF27: =SUM(U27:Z27,P27) -> 766.3 | AG27: =SUM(AB27:AF27) -> 2587.1
A28: Rural+Urban | B28: 2013 | C28: September | D28: 116.4 | E28: 116.9 | F28: 112.3 | G28: 110.5 | H28: 105.3 | I28: 107.3 | J28: 160.9 | K28: 107.1 | L28: 103.1 | M28: 108.3 | N28: 110.7 | O28: 114.6 | P28: 112 | Q28: 112.2 | R28: 110.4 | S28: 109.7 | T28: 110.5 | U28: 109.6 | V28: 108.1 | W28: 109.9 | X28: 107.5 | Y28: 110.6 | Z28: 106.8 | AA28: 113.7 | AB28: =SUM(D28:O28) -> 1373.4 | AC28: 109.7 | AD28: 110.5 | AE28: =SUM(Q28:R28) -> 222.6 | AF28: =SUM(U28:Z28,P28) -> 764.5 | AG28: =SUM(AB28:AF28) -> 2580.7
A29: Rural | B29: 2013 | C29: October | D29: 116.3 | E29: 115.4 | F29: 112.6 | G29: 111.7 | H29: 107.7 | I29: 113.2 | J29: 164.9 | K29: 108.3 | L29: 103.9 | M29: 108.2 | N29: 111.1 | O29: 114.9 | P29: 112.2 | Q29: 113.6 | R29: 112.3 | T29: 111.6 | U29: 110.4 | V29: 108.9 | W29: 109.3 | X29: 108.3 | Y29: 110.2 | Z29: 107.5 | AA29: 115.5 | AB29: =SUM(D29:O29) -> 1388.2 | AD29: 111.6 | AE29: =SUM(Q29:R29) -> 225.9 | AF29: =SUM(U29:Z29,P29) -> 766.8 | AG29: =SUM(AB29:AF29) -> 2492.5
A30: Urban | B30: 2013 | C30: October | D30: 118.9 | E30: 118.1 | F30: 114.5 | G30: 110.4 | H30: 102.3 | I30: 106.2 | J30: 183.5 | K30: 105.3 | L30: 100.2 | M30: 109.6 | N30: 111.4 | O30: 116 | P30: 113.5 | Q30: 112.5 | R30: 109.7 | S30: 110.5 | T30: 109.7 | U30: 110.2 | V30: 108.2 | W30: 109.7 | X30: 108 | Y30: 111.3 | Z30: 107.3 | AA30: 114 | AB30: =SUM(D30:O30) -> 1396.4 | AC30: 110.5 | AD30: 109.7 | AE30: =SUM(Q30:R30) -> 222.2 | AF30: =SUM(U30:Z30,P30) -> 768.2 | AG30: =SUM(AB30:AF30) -> 2607
A31: Rural+Urban | B31: 2013 | C31: October | D31: 117.1 | E31: 116.3 | F31: 113.3 | G31: 111.2 | H31: 105.7 | I31: 109.9 | J31: 171.2 | K31: 107.3 | L31: 102.7 | M31: 108.7 | N31: 111.2 | O31: 115.4 | P31: 112.5 | Q31: 113.2 | R31: 111.2 | S31: 110.5 | T31: 110.9 | U31: 110.3 | V31: 108.6 | W31: 109.5 | X31: 108.1 | Y31: 110.8 | Z31: 107.4 | AA31: 114.8 | AB31: =SUM(D31:O31) -> 1390 | AC31: 110.5 | AD31: 110.9 | AE31: =SUM(Q31:R31) -> 224.4 | AF31: =SUM(U31:Z31,P31) -> 767.2 | AG31: =SUM(AB31:AF31) -> 2603
A32: Rural | B32: 2013 | C32: November | D32: 117.3 | E32: 114.9 | F32: 116.2 | G32: 112.8 | H32: 108.9 | I32: 116.6 | J32: 178.1 | K32: 109.1 | L32: 103.6 | M32: 109 | N32: 111.8 | O32: 116 | P32: 112.8 | Q32: 114.6 | R32: 113.1 | T32: 112.6 | U32: 111.3 | V32: 109.7 | W32: 109.6 | X32: 108.7 | Y32: 111 | Z32: 108.2 | AA32: 117.4 | AB32: =SUM(D32:O32) -> 1414.3 | AD32: 112.6 | AE32: =SUM(Q32:R32) -> 227.7 | AF32: =SUM(U32:Z32,P32) -> 771.3 | AG32: =SUM(AB32:AF32) -> 2525.9
A33: Urban | B33: 2013 | C33: November | D33: 119.8 | E33: 116.3 | F33: 122.6 | G33: 112 | H33: 103.2 | I33: 110 | J33: 192.8 | K33: 106.3 | L33: 99.5 | M33: 110.3 | N33: 111.8 | O33: 117.1 | P33: 114.1 | Q33: 113.5 | R33: 110.3 | S33: 111.1 | T33: 110 | U33: 110.9 | V33: 108.6 | W33: 109.5 | X33: 108.5 | Y33: 111.3 | Z33: 107.9 | AA33: 115 | AB33: =SUM(D33:O33) -> 1421.7 | AC33: 111.1 | AD33: 110 | AE33: =SUM(Q33:R33) -> 223.8 | AF33: =SUM(U33:Z33,P33) -> 770.8 | AG33: =SUM(AB33:AF33) -> 2637.4
A34: Rural+Urban | B34: 2013 | C34: November | D34: 118.1 | E34: 115.4 | F34: 118.7 | G34: 112.5 | H34: 106.8 | I34: 113.5 | J34: 183.1 | K34: 108.2 | L34: 102.2 | M34: 109.4 | N34: 111.8 | O34: 116.5 | P34: 113.1 | Q34: 114.2 | R34: 111.9 | S34: 111.1 | T34: 111.6 | U34: 111.1 | V34: 109.3 | W34: 109.5 | X34: 108.6 | Y34: 111.2 | Z34: 108.1 | AA34: 116.3 | AB34: =SUM(D34:O34) -> 1416.2 | AC34: 111.1 | AD34: 111.6 | AE34: =SUM(Q34:R34) -> 226.1 | AF34: =SUM(U34:Z34,P34) -> 770.9 | AG34: =SUM(AB34:AF34) -> 2635.9
A35: Rural | B35: 2013 | C35: December | D35: 118.4 | E35: 115.9 | F35: 120.4 | G35: 113.8 | H35: 109.5 | I35: 115.5 | J35: 145.7 | K35: 109.5 | L35: 102.9 | M35: 109.8 | N35: 112.1 | O35: 116.8 | P35: 113.6 | Q35: 115.8 | R35: 114 | T35: 112.8 | U35: 112.1 | V35: 110.1 | W35: 109.9 | X35: 109.2 | Y35: 111.6 | Z35: 108.1 | AA35: 115.5 | AB35: =SUM(D35:O35) -> 1390.3 | AD35: 112.8 | AE35: =SUM(Q35:R35) -> 229.8 | AF35: =SUM(U35:Z35,P35) -> 774.6 | AG35: =SUM(AB35:AF35) -> 2507.5
A36: Urban | B36: 2013 | C36: December | D36: 120.5 | E36: 118.1 | F36: 128.5 | G36: 112.8 | H36: 103.4 | I36: 110.7 | J36: 144.8 | K36: 107.1 | L36: 98.6 | M36: 111.9 | N36: 112.1 | O36: 118.1 | P36: 115 | Q36: 114.2 | R36: 110.9 | S36: 110.7 | T36: 110.4 | U36: 111.3 | V36: 109 | W36: 109.7 | X36: 108.9 | Y36: 111.4 | Z36: 107.7 | AA36: 113.3 | AB36: =SUM(D36:O36) -> 1386.6 | AC36: 110.7 | AD36: 110.4 | AE36: =SUM(Q36:R36) -> 225.1 | AF36: =SUM(U36:Z36,P36) -> 773 | AG36: =SUM(AB36:AF36) -> 2605.8
A37: Rural+Urban | B37: 2013 | C37: December | D37: 119.1 | E37: 116.7 | F37: 123.5 | G37: 113.4 | H37: 107.3 | I37: 113.3 | J37: 145.4 | K37: 108.7 | L37: 101.5 | M37: 110.5 | N37: 112.1 | O37: 117.4 | P37: 114 | Q37: 115.2 | R37: 112.7 | S37: 110.7 | T37: 111.9 | U37: 111.7 | V37: 109.7 | W37: 109.8 | X37: 109 | Y37: 111.5 | Z37: 107.9 | AA37: 114.5 | AB37: =SUM(D37:O37) -> 1388.9 | AC37: 110.7 | AD37: 111.9 | AE37: =SUM(Q37:R37) -> 227.9 | AF37: =SUM(U37:Z37,P37) -> 773.6 | AG37: =SUM(AB37:AF37) -> 2613
A38: Rural | B38: 2014 | C38: January | D38: 118.9 | E38: 117.1 | F38: 120.5 | G38: 114.4 | H38: 109 | I38: 115.5 | J38: 123.9 | K38: 109.6 | L38: 101.8 | M38: 110.2 | N38: 112.4 | O38: 117.3 | P38: 114 | Q38: 116.5 | R38: 114.5 | T38: 113 | U38: 112.6 | V38: 110.6 | W38: 110.5 | X38: 109.6 | Y38: 111.8 | Z38: 108.3 | AA38: 114.2 | AB38: =SUM(D38:O38) -> 1370.6 | AD38: 113 | AE38: =SUM(Q38:R38) -> 231 | AF38: =SUM(U38:Z38,P38) -> 777.4 | AG38: =SUM(AB38:AF38) -> 2492
A39: Urban | B39: 2014 | C39: January | D39: 121.2 | E39: 122 | F39: 129.9 | G39: 113.6 | H39: 102.9 | I39: 112.1 | J39: 118.9 | K39: 107.5 | L39: 96.9 | M39: 112.7 | N39: 112.1 | O39: 119 | P39: 115.7 | Q39: 114.8 | R39: 111.3 | S39: 111.6 | T39: 111 | U39: 111.9 | V39: 109.7 | W39: 110.8 | X39: 109.8 | Y39: 111.5 | Z39: 108 | AA39: 112.9 | AB39: =SUM(D39:O39) -> 1368.8 | AC39: 111.6 | AD39: 111 | AE39: =SUM(Q39:R39) -> 226.1 | AF39: =SUM(U39:Z39,P39) -> 777.4 | AG39: =SUM(AB39:AF39) -> 2594.9
A40: Rural+Urban | B40: 2014 | C40: January | D40: 119.6 | E40: 118.8 | F40: 124.1 | G40: 114.1 | H40: 106.8 | I40: 113.9 | J40: 122.2 | K40: 108.9 | L40: 100.2 | M40: 111 | N40: 112.3 | O40: 118.1 | P40: 114.5 | Q40: 115.8 | R40: 113.2 | S40: 111.6 | T40: 112.2 | U40: 112.3 | V40: 110.3 | W40: 110.7 | X40: 109.7 | Y40: 111.6 | Z40: 108.2 | AA40: 113.6 | AB40: =SUM(D40:O40) -> 1370 | AC40: 111.6 | AD40: 112.2 | AE40: =SUM(Q40:R40) -> 229 | AF40: =SUM(U40:Z40,P40) -> 777.3 | AG40: =SUM(AB40:AF40) -> 2600.1
...

Sheet ANSWER 1
A1: QUESTION 1
B6: FOOD CONTRIBUTION | C6: = | D6: =('MAIN DATA'!AB$373/'MAIN DATA'!$AG$373)*100 -> 51.728497
B7: HOUSING CONTRIBUTION | C7: = | D7: =('MAIN DATA'!AC$373/'MAIN DATA'!$AG$373)*100 -> 4.2689746
B8: FUEL AND LIGHT CONTRIBUTION | C8: = | D8: =('MAIN DATA'!AD$373/'MAIN DATA'!$AG$373)*100 -> 4.4440123
B9: CLOTHING AND FOOTWEAR CONTRIBUTION | C9: = | D9: =('MAIN DATA'!AE$373/'MAIN DATA'!$AG$373)*100 -> 8.9220596
B10: MISCELLANEOUS CONTRIBUTION | C10: = | D10: =('MAIN DATA'!AF$373/'MAIN DATA'!$AG$373)*100 -> 30.636456
B12: FOOD AND BEVERAGES HAS THE HIGHEST CONTRIBUTION IN CPI CALCULATION

Sheet ANSWER 2
A1: Sector | B1: Year | C1: Month | D1: General index | E1: YOY INFLATION %
A2: Rural+Urban | B2: 2013 | C2: January | D2: 104.6
A3: Rural+Urban | B3: 2013 | C3: February | D3: 105.3
A4: Rural+Urban | B4: 2013 | C4: March | D4: 105.5
A5: Rural+Urban | B5: 2013 | C5: April | D5: 106.1
A6: Rural+Urban | B6: 2013 | C6: May | D6: 106.9
A7: Rural+Urban | B7: 2013 | C7: June | D7: 109.3
A8: Rural+Urban | B8: 2013 | C8: July | D8: 111
A9: Rural+Urban | B9: 2013 | C9: August | D9: 112.4
A10: Rural+Urban | B10: 2013 | C10: September | D10: 113.7
A11: Rural+Urban | B11: 2013 | C11: October | D11: 114.8
A12: Rural+Urban | B12: 2013 | C12: November | D12: 116.3
A13: Rural+Urban | B13: 2013 | C13: December | D13: 114.5
A14: Rural+Urban | B14: 2014 | C14: January | D14: 113.6 | E14: =((D14-D2)/D2)*100 -> 8.6042065
A15: Rural+Urban | B15: 2014 | C15: February | D15: 113.6 | E15: =((D15-D3)/D3)*100 -> 7.8822412
A16: Rural+Urban | B16: 2014 | C16: March | D16: 114.2 | E16: =((D16-D4)/D4)*100 -> 8.2464455
A17: Rural+Urban | B17: 2014 | C17: April | D17: 115.1 | E17: =((D17-D5)/D5)*100 -> 8.4825636
A18: Rural+Urban | B18: 2014 | C18: May | D18: 115.8 | E18: =((D18-D6)/D6)*100 -> 8.3255379
A19: Rural+Urban | B19: 2014 | C19: June | D19: 116.7 | E19: =((D19-D7)/D7)*100 -> 6.7703568
A20: Rural+Urban | B20: 2014 | C20: July | D20: 119.2 | E20: =((D20-D8)/D8)*100 -> 7.3873874
A21: Rural+Urban | B21: 2014 | C21: August | D21: 120.3 | E21: =((D21-D9)/D9)*100 -> 7.0284698
A22: Rural+Urban | B22: 2014 | C22: September | D22: 120.1 | E22: =((D22-D10)/D10)*100 -> 5.6288478
A23: Rural+Urban | B23: 2014 | C23: October | D23: 120.1 | E23: =((D23-D11)/D11)*100 -> 4.6167247 | I23: 2022 HAS THE HIGHEST INFLATION N RATE
A24: Rural+Urban | B24: 2014 | C24: November | D24: 120.1 | E24: =((D24-D12)/D12)*100 -> 3.2674119 | I24: REASONS
A25: Rural+Urban | B25: 2014 | C25: December | D25: 119.4 | E25: =((D25-D13)/D13)*100 -> 4.279476 | I25: 1) IMPORTED INFLATION (CRUDE OIL)p
A26: Rural+Urban | B26: 2015 | C26: January | D26: 119.5 | E26: =((D26-D14)/D14)*100 -> 5.193662 | I26: 2) EDIBLE OIL AND COMMODITY SHOCKS
A27: Rural+Urban | B27: 2015 | C27: February | D27: 119.7 | E27: =((D27-D15)/D15)*100 -> 5.3697183 | I27: 3) POST-PANDEMIC DEMAND
A28: Rural+Urban | B28: 2015 | C28: March | D28: 120.2 | E28: =((D28-D16)/D16)*100 -> 5.2539405
A29: Rural+Urban | B29: 2015 | C29: April | D29: 120.7 | E29: =((D29-D17)/D17)*100 -> 4.8653345
A30: Rural+Urban | B30: 2015 | C30: May | D30: 121.6 | E30: =((D30-D18)/D18)*100 -> 5.0086356
A31: Rural+Urban | B31: 2015 | C31: June | D31: 123 | E31: =((D31-D19)/D19)*100 -> 5.3984576
A32: Rural+Urban | B32: 2015 | C32: July | D32: 123.6 | E32: =((D32-D20)/D20)*100 -> 3.6912752
A33: Rural+Urban | B33: 2015 | C33: August | D33: 124.8 | E33: =((D33-D21)/D21)*100 -> 3.7406484
A34: Rural+Urban | B34: 2015 | C34: September | D34: 125.4 | E34: =((D34-D22)/D22)*100 -> 4.4129892
A35: Rural+Urban | B35: 2015 | C35: October | D35: 126.1 | E35: =((D35-D23)/D23)*100 -> 4.9958368
A36: Rural+Urban | B36: 2015 | C36: November | D36: 126.6 | E36: =((D36-D24)/D24)*100 -> 5.4121565
A37: Rural+Urban | B37: 2015 | C37: December | D37: 126.1 | E37: =((D37-D25)/D25)*100 -> 5.6113903
A38: Rural+Urban | B38: 2016 | C38: January | D38: 126.3 | E38: =((D38-D26)/D26)*100 -> 5.6903766
A39: Rural+Urban | B39: 2016 | C39: February | D39: 126 | E39: =((D39-D27)/D27)*100 -> 5.2631579
... A125: Rural+Urban | B125: 2023 | C125: May | D125: 179.1 | E125: =((D125-D113)/D113)*100 -> 4.3098427

Sheet ANSWER 3
A1: SECTOR | B1: YEAR | C1: MONTH | D1: FOOD AND BEVERAGES | E1: FOOD MOM%Q
A2: Rural+Urban | B2: 2022 | C2: May | D2: 2065.6 | G2: MONTH WITH HIGHEST INFLATION IS JUNE 2022
A3: Rural+Urban | B3: 2022 | C3: June | D3: 2087 | E3: =((D3-D2)/D2) -> 0.010360186 | G3: MONTH WITH LOWEST INFLATION IS FEBRUARY 2023
A4: Rural+Urban | B4: 2022 | C4: July | D4: 2091.3 | E4: =((D4-D3)/D3) -> 0.0020603737
A5: Rural+Urban | B5: 2022 | C5: August | D5: 2092.9 | E5: =((D5-D4)/D4) -> 0.00076507436
A6: Rural+Urban | B6: 2022 | C6: September | D6: 2103.1 | E6: =((D6-D5)/D5) -> 0.0048736203
A7: Rural+Urban | B7: 2022 | C7: October | D7: 2117.7 | E7: =((D7-D6)/D6) -> 0.006942133
A8: Rural+Urban | B8: 2022 | C8: November | D8: 2118.5 | E8: =((D8-D7)/D7) -> 0.00037776833
A9: Rural+Urban | B9: 2022 | C9: December | D9: 2107.5 | E9: =((D9-D8)/D8) -> -0.0051923531
A10: Rural+Urban | B10: 2023 | C10: January | D10: 2116 | E10: =((D10-D9)/D9) -> 0.0040332147
A11: Rural+Urban | B11: 2023 | C11: February | D11: 2102.1 | E11: =((D11-D10)/D10) -> -0.0065689981
A12: Rural+Urban | B12: 2023 | C12: March | D12: 2102.2 | E12: =((D12-D11)/D11) -> 4.7571476e-05
A13: Rural+Urban | B13: 2023 | C13: April | D13: 2111.7 | E13: =((D13-D12)/D12) -> 0.0045190753
A14: Rural+Urban | B14: 2023 | C14: May | D14: 2127.8 | E14: =((D14-D13)/D13) -> 0.007624189 | I14: SPICES IS THE BIGGEST INDIVIDUAL CATEGORY CONTRIBUTOR
A17: Sector | B17: Year | C17: Month | D17: Cereals and products | E17: Meat and fish | F17: Egg | G17: Milk and products | H17: Oils and fats | I17: Fruits | J17: Vegetables | K17: Pulses and products | L17: Sugar and Confectionery | M17: Spices | N17: Non-alcoholic beverages | O17: Prepared meals, snacks, sweets etc.
A18: Rural+Urban | B18: 2022 | C18: May | D18: 154.1 | E18: 217 | F18: 162.4 | G18: 164.9 | H18: 202.4 | I18: 171 | J18: 174.9 | K18: 164.7 | L18: 119.7 | M18: 184.9 | N18: 167.1 | O18: 182.5
A19: Rural+Urban | B19: 2022 | C19: June | D19: 155 | E19: 219.4 | F19: 170.8 | G19: 165.8 | H19: 200.9 | I19: 169.7 | J19: 182.3 | K19: 164.3 | L19: 119.9 | M19: 187.1 | N19: 167.9 | O19: 183.9
A20: Rural+Urban | B20: 2022 | C20: July | D20: 156.5 | E20: 213 | F20: 175.2 | G20: 166.6 | H20: 195.8 | I20: 174.2 | J20: 182.1 | K20: 164.3 | L20: 120 | M20: 190 | N20: 168.4 | O20: 185.2
A21: Rural+Urban | B21: 2022 | C21: August | D21: 160.3 | E21: 206.5 | F21: 169.2 | G21: 168.1 | H21: 192.4 | I21: 172.9 | J21: 186.7 | K21: 167.2 | L21: 120.9 | M21: 193.6 | N21: 168.8 | O21: 186.3
A22: Rural+Urban | B22: 2022 | C22: September | D22: 163.5 | E22: 209.2 | F22: 169.7 | G22: 169.7 | H22: 188.7 | I22: 165.7 | J22: 191.8 | K22: 169.1 | L22: 121.6 | M22: 197.3 | N22: 169.4 | O22: 187.4
A23: Rural+Urban | B23: 2022 | C23: October | D23: 165.2 | E23: 210.9 | F23: 170.9 | G23: 170.9 | H23: 186.5 | I23: 163.8 | J23: 199.7 | K23: 169.8 | L23: 121.9 | M23: 199.9 | N23: 169.9 | O23: 188.3
A24: Rural+Urban | B24: 2022 | C24: November | D24: 167.4 | E24: 209.4 | F24: 181.4 | G24: 172.3 | H24: 188.9 | I24: 160.7 | J24: 183.1 | K24: 170.5 | L24: 122.1 | M24: 202.8 | N24: 170.4 | O24: 189.5
A25: Rural+Urban | B25: 2022 | C25: December | D25: 169.2 | E25: 209 | F25: 190.2 | G25: 173.6 | H25: 188.5 | I25: 158 | J25: 159.9 | K25: 170.8 | L25: 121.8 | M25: 205.2 | N25: 171 | O25: 190.3
A26: Rural+Urban | B26: 2023 | C26: January | D26: 173.8 | E26: 210.7 | F26: 194.5 | G26: 174.6 | H26: 187.2 | I26: 158.3 | J26: 153.9 | K26: 170.9 | L26: 121.1 | M26: 208.4 | N26: 171.4 | O26: 191.2
A27: Rural+Urban | B27: 2023 | C27: February | D27: 174.4 | E27: 207.7 | F27: 175.2 | G27: 177.3 | H27: 179.3 | I27: 169.5 | J27: 152.7 | K27: 171 | L27: 120 | M27: 209.7 | N27: 172.3 | O27: 193
A28: Rural+Urban | B28: 2023 | C28: March | D28: 174.4 | E28: 207.7 | F28: 175.2 | G28: 177.3 | H28: 179.2 | I28: 169.5 | J28: 152.8 | K28: 171.1 | L28: 120 | M28: 209.7 | N28: 172.3 | O28: 193
A29: Rural+Urban | B29: 2023 | C29: April | D29: 173.8 | E29: 209.3 | F29: 169.6 | G29: 178.4 | H29: 174.9 | I29: 176.3 | J29: 155.4 | K29: 173.4 | L29: 121.3 | M29: 212.9 | N29: 172.9 | O29: 193.5
A30: Rural+Urban | B30: 2023 | C30: May | D30: 173.7 | E30: 214.3 | F30: 173.2 | G30: 179.5 | H30: 170 | I30: 172.2 | J30: 161 | K30: 175.6 | L30: 122.7 | M30: 218 | N30: 173.4 | O30: 194.2
D32: =D30-D19 -> 18.7 | E32: =E30-E19 -> -5.1 | F32: =F30-F19 -> 2.4 | G32: =G30-G19 -> 13.7 | H32: =H30-H19 -> -30.9 | I32: =I30-I19 -> 2.5 | J32: =J30-J19 -> -21.3 | K32: =K30-K19 -> 11.3 | ... O32: =O30-O19 -> 10.3

Sheet ANSWER 4
A1: Sector | B1: Year | C1: Month | D1: FOOD AND BEVERAGES | E1: Health | F1: Household goods and services | H1: FOOD COVID | I1: HEALTH COVID | J1: Household goods and services COVID
A2: Rural+Urban | B2: 2019 | C2: March | D2: 1624.8 | E2: 146.2 | F2: 143.8 | G2: PRE COVID INFLATION= | H2: =(D13-D2)/D2 -> 0.074901526 | I2: =(E13-E2)/E2 -> 0.041723666 | J2: =(F13-F2)/F2 -> 0.018080668
A3: Rural+Urban | B3: 2019 | C3: May | D3: 1651 | E3: 146.9 | F3: 143.7 | G3: POST COVID INFLATIO= | H3: =(D25-D13)/D13 -> 0.077984541 | I3: =(E25-E13)/E13 -> 0.061720289 | J3: =(F25-F13)/F13 -> 0.032786885
A4: Rural+Urban | B4: 2019 | C4: June | D4: 1671.4 | E4: 147.4 | F4: 143.8
A5: Rural+Urban | B5: 2019 | C5: July | D5: 1692.8 | E5: 147.9 | F5: 144.2 | G5: THE REASON WE CAN SEE THE NOTICEABLE SPIKE IN INFLATION:
A6: Rural+Urban | B6: 2019 | C6: August | D6: 1700.6 | E6: 148.5 | F6: 144.5 | I6: 1) FOOD INFLATION SPIKED
A7: Rural+Urban | B7: 2019 | C7: September | D7: 1710.7 | E7: 149 | F7: 144.6 | I7: 2) HEALTHCARE INFLATION JUMPED
A8: Rural+Urban | B8: 2019 | C8: October | D8: 1736 | E8: 149.4 | F8: 145 | I8: 3) ESSENTIAL SERVICES
A9: Rural+Urban | B9: 2019 | C9: November | D9: 1759 | E9: 149.9 | F9: 145.3
A10: Rural+Urban | B10: 2019 | C10: December | D10: 1791.1 | E10: 150.4 | F10: 145.8
A11: Rural+Urban | B11: 2020 | C11: January | D11: 1786.9 | E11: 151.2 | F11: 146.2
A12: Rural+Urban | B12: 2020 | C12: February | D12: 1761.1 | E12: 151.7 | F12: 146.4
A13: Rural+Urban | B13: 2020 | C13: March | D13: 1746.5 | E13: 152.3 | F13: 146.4
A14: Rural+Urban | B14: 2020 | C14: April | D14: 1811.85 | E14: 150.7 | F14: 146.4
A15: Rural+Urban | B15: 2020 | C15: May | D15: 1805.35 | E15: 152.55 | F15: 146.4
A16: Rural+Urban | B16: 2020 | C16: June | D16: 1812.8 | E16: 154.4 | F16: 146.4
A17: Rural+Urban | B17: 2020 | C17: July | D17: 1812.8 | E17: 154.4 | F17: 146.4
A18: Rural+Urban | B18: 2020 | C18: August | D18: 1838.2 | E18: 155 | F18: 148.4
A19: Rural+Urban | B19: 2020 | C19: September | D19: 1849 | E19: 155.6 | F19: 148.7
A20: Rural+Urban | B20: 2020 | C20: October | D20: 1887.2 | E20: 156.3 | F20: 148.7
... A34: Rural+Urban | B34: 2021 | C34: December | D34: 2012.7 | E34: 170.6 | F34: 160.2

Sheet ANSWER 5
A1: Sector | B1: Year | C1: Month | D1: FOOD AND BEVERAGES | E1: HOUSING | F1: FUEL AND LIGHT | G1: CLOTHING AND FOOTWEAR | H1: MISCELLANEOUS | I1: CRUDE OIL PRICES | J1: crude MOM% | K1: FOOD AND BEVERAGES mom% | L1: HOUSING mom% | M1: FUEL AND LIGHT mom% | N1: CLOTHING AND FOOTWEAR mom% | O1: MISCELLANEOUS mom%
A2: Rural+Urban | B2: 2021 | C2: January | D2: 1915.5 | E2: 157.7 | F2: 147.9 | G2: 301.6 | H2: 1103.3 | I2: 54.77
A3: Rural+Urban | B3: 2021 | C3: February | D3: 1882.4 | E3: 159.8 | F3: 152.4 | G3: 304.6 | H3: 1112.4 | I3: 62.28 | J3: =(I3-I2)/I2 -> 0.13711886 | K3: =(D3-D2)/D2 -> -0.017280084 | L3: =(E3-E2)/E2 -> 0.013316424 | M3: =(F3-F2)/F2 -> 0.030425963 | N3: =(G3-G2)/G2 -> 0.0099469496 | O3: =(H3-H2)/H2 -> 0.0082479833 | P3: testing oil vs food | Q3: =CORREL($J$3:$J$30,$K$3:$K$30) -> 0.051935438
A4: Rural+Urban | B4: 2021 | C4: March | D4: 1882.7 | E4: 159.9 | F4: 155.5 | G4: 305.7 | H4: 1113.8 | I4: 65.41 | J4: =(I4-I3)/I3 -> 0.050256904 | K4: =(D4-D3)/D3 -> 0.00015937102 | L4: =(E4-E3)/E3 -> 0.00062578223 | M4: =(F4-F3)/F3 -> 0.020341207 | N4: =(G4-G3)/G3 -> 0.0036112935 | O4: =(H4-H3)/H3 -> 0.0012585401 | P4: testing oil vs housing | Q4: =CORREL($J$3:$J$30,$L$3:$L$30) -> 0.12627535
A5: Rural+Urban | B5: 2021 | C5: April | D5: 1906.1 | E5: 161.4 | F5: 155.6 | G5: 307.3 | H5: 1118.4 | I5: 64.81 | J5: =(I5-I4)/I4 -> -0.0091729093 | K5: =(D5-D4)/D4 -> 0.012428958 | L5: =(E5-E4)/E4 -> 0.009380863 | M5: =(F5-F4)/F4 -> 0.00064308682 | N5: =(G5-G4)/G4 -> 0.0052338894 | O5: =(H5-H4)/H4 -> 0.0041300054 | P5: testing oil vs fuel | Q5: =CORREL($J$3:$J$30,$M$3:$M$30) -> 0.12569723
A6: Rural+Urban | B6: 2021 | C6: May | D6: 1945 | E6: 161.6 | F6: 159.4 | G6: 313.9 | H6: 1136.9 | I6: 68.53 | J6: =(I6-I5)/I5 -> 0.05739855 | K6: =(D6-D5)/D5 -> 0.020408163 | L6: =(E6-E5)/E5 -> 0.0012391574 | M6: =(F6-F5)/F5 -> 0.024421594 | N6: =(G6-G5)/G5 -> 0.021477384 | O6: =(H6-H5)/H5 -> 0.016541488 | P6: testing oil vs clothing | Q6: =CORREL($J$3:$J$30,$N$3:$N$30) -> 0.15307794
A7: Rural+Urban | B7: 2021 | C7: June | D7: 1971.3 | E7: 160.5 | F7: 159.8 | G7: 314 | H7: 1138 | I7: 73.16 | J7: =(I7-I6)/I6 -> 0.067561652 | K7: =(D7-D6)/D6 -> 0.013521851 | L7: =(E7-E6)/E6 -> -0.0068069307 | M7: =(F7-F6)/F6 -> 0.0025094103 | N7: =(G7-G6)/G6 -> 0.00031857279 | O7: =(H7-H6)/H6 -> 0.00096754332 | P7: testing oil vs misc | Q7: =CORREL($J$3:$J$30,$O$3:$O$30) -> 0.08118428
A8: Rural+Urban | B8: 2021 | C8: July | D8: 1983 | E8: 161.5 | F8: 160.7 | G8: 315.9 | H8: 1145.7 | I8: 75.17 | J8: =(I8-I7)/I7 -> 0.02747403 | K8: =(D8-D7)/D7 -> 0.0059351697 | L8: =(E8-E7)/E7 -> 0.0062305296 | M8: =(F8-F7)/F7 -> 0.0056320401 | N8: =(G8-G7)/G7 -> 0.0060509554 | O8: =(H8-H7)/H7 -> 0.0067662566
A9: Rural+Urban | B9: 2021 | C9: August | D9: 1978 | E9: 162.1 | F9: 162.6 | G9: 319.8 | H9: 1153.4 | I9: 70.75 | J9: =(I9-I8)/I8 -> -0.058800053 | K9: =(D9-D8)/D8 -> -0.0025214322 | L9: =(E9-E8)/E8 -> 0.0037151703 | M9: =(F9-F8)/F8 -> 0.011823273 | N9: =(G9-G8)/G8 -> 0.012345679 | O9: =(H9-H8)/H8 -> 0.0067207821
A10: Rural+Urban | B10: 2021 | C10: September | D10: 1978 | E10: 162.1 | F10: 162.6 | G10: 319.9 | H10: 1153.4 | I10: 74.49 | J10: =(I10-I9)/I9 -> 0.052862191 | K10: =(D10-D9)/D9 -> -1.149513e-16 | L10: =(E10-E9)/E9 -> 0 | M10: =(F10-F9)/F9 -> 0 | N10: =(G10-G9)/G9 -> 0.00031269543 | O10: =(H10-H9)/H9 -> 0
A11: Rural+Urban | B11: 2021 | C11: October | D11: 2007.8 | E11: 163.6 | F11: 164.2 | G11: 322 | H11: 1159.2 | I11: 83.54 | J11: =(I11-I10)/I10 -> 0.12149282 | K11: =(D11-D10)/D10 -> 0.015065723 | L11: =(E11-E10)/E10 -> 0.0092535472 | M11: =(F11-F10)/F10 -> 0.0098400984 | N11: =(G11-G10)/G10 -> 0.0065645514 | O11: =(H11-H10)/H10 -> 0.0050286111 | P11: clothing category shows the strongest correlation to global crude oil price
A12: Rural+Urban | B12: 2021 | C12: November | D12: 2024.4 | E12: 164.2 | F12: 163.9 | G12: 324.6 | H12: 1163.2 | I12: 81.05 | J12: =(I12-I11)/I11 -> -0.029806081 | K12: =(D12-D11)/D11 -> 0.0082677558 | L12: =(E12-E11)/E11 -> 0.0036674817 | M12: =(F12-F11)/F11 -> -0.0018270402 | N12: =(G12-G11)/G11 -> 0.0080745342 | O12: =(H12-H11)/H11 -> 0.0034506556
A13: Rural+Urban | B13: 2021 | C13: December | D13: 2012.7 | E13: 163.4 | F13: 164.1 | G13: 327.2 | H13: 1166.5 | I13: 74.17 | J13: =(I13-I12)/I12 -> -0.084885873 | K13: =(D13-D12)/D12 -> -0.0057794902 | L13: =(E13-E12)/E12 -> -0.0048721072 | M13: =(F13-F12)/F12 -> 0.0012202563 | N13: =(G13-G12)/G12 -> 0.0080098583 | O13: =(H13-H12)/H12 -> 0.0028370014
A14: Rural+Urban | B14: 2022 | C14: January | D14: 1997.8 | E14: 164.5 | F14: 164.2 | G14: 330.6 | H14: 1170.1 | I14: 86.51 | J14: =(I14-I13)/I13 -> 0.16637454 | K14: =(D14-D13)/D13 -> -0.007402991 | L14: =(E14-E13)/E13 -> 0.0067319461 | M14: =(F14-F13)/F13 -> 0.00060938452 | N14: =(G14-G13)/G13 -> 0.010391198 | O14: =(H14-H13)/H13 -> 0.0030861552
A15: Rural+Urban | B15: 2022 | C15: February | D15: 1995 | E15: 165.5 | F15: 165.7 | G15: 333.2 | H15: 1175.6 | I15: 97.13 | J15: =(I15-I14)/I14 -> 0.12276037 | K15: =(D15-D14)/D14 -> -0.0014015417 | L15: =(E15-E14)/E14 -> 0.0060790274 | M15: =(F15-F14)/F14 -> 0.009135201 | N15: =(G15-G14)/G14 -> 0.0078644888 | O15: =(H15-H14)/H14 -> 0.004700453
A16: Rural+Urban | B16: 2022 | C16: March | D16: 2015.8 | E16: 165.3 | F16: 167.2 | G16: 336.7 | H16: 1183.9 | I16: 117.25 | J16: =(I16-I15)/I15 -> 0.20714506 | K16: =(D16-D15)/D15 -> 0.010426065 | L16: =(E16-E15)/E15 -> -0.0012084592 | M16: =(F16-F15)/F15 -> 0.0090525045 | N16: =(G16-G15)/G15 -> 0.010504202 | O16: =(H16-H15)/H15 -> 0.0070602246
A17: Rural+Urban | B17: 2022 | C17: April | D17: 2043.5 | E17: 167 | F17: 172.2 | G17: 340.4 | H17: 1194.6 | I17: 104.58 | J17: =(I17-I16)/I16 -> -0.1080597 | K17: =(D17-D16)/D16 -> 0.013741443 | L17: =(E17-E16)/E16 -> 0.010284332 | M17: =(F17-F16)/F16 -> 0.029904306 | N17: =(G17-G16)/G16 -> 0.010989011 | O17: =(H17-H16)/H16 -> 0.0090379255
A18: Rural+Urban | B18: 2022 | C18: May | D18: 2065.6 | E18: 167.5 | F18: 174.6 | G18: 344 | H18: 1198.5 | I18: 113.34 | J18: =(I18-I17)/I17 -> 0.083763626 | K18: =(D18-D17)/D17 -> 0.010814779 | L18: =(E18-E17)/E17 -> 0.002994012 | M18: =(F18-F17)/F17 -> 0.013937282 | N18: =(G18-G17)/G17 -> 0.010575793 | O18: =(H18-H17)/H17 -> 0.0032646911
A19: Rural+Urban | B19: 2022 | C19: June | D19: 2087 | E19: 166.8 | F19: 176 | G19: 347 | H19: 1201.4 | I19: 122.71 | J19: =(I19-I18)/I18 -> 0.082671608 | K19: =(D19-D18)/D18 -> 0.010360186 | L19: =(E19-E18)/E18 -> -0.0041791045 | M19: =(F19-F18)/F18 -> 0.0080183276 | N19: =(G19-G18)/G18 -> 0.0087209302 | O19: =(H19-H18)/H18 -> 0.0024196913
A20: Rural+Urban | B20: 2022 | C20: July | D20: 2091.3 | E20: 167.8 | F20: 179.6 | G20: 349.6 | H20: 1207.1 | I20: 111.93 | J20: =(I20-I19)/I19 -> -0.087849401 | K20: =(D20-D19)/D19 -> 0.0020603737 | L20: =(E20-E19)/E19 -> 0.0059952038 | M20: =(F20-F19)/F19 -> 0.020454545 | N20: =(G20-G19)/G19 -> 0.0074927954 | O20: =(H20-H19)/H19 -> 0.0047444648
A21: Rural+Urban | B21: 2022 | C21: August | D21: 2092.9 | E21: 169 | F21: 178.8 | G21: 352.2 | H21: 1212.6 | I21: 100.45 | J21: =(I21-I20)/I20 -> -0.1025641 | K21: =(D21-D20)/D20 -> 0.00076507436 | L21: =(E21-E20)/E20 -> 0.0071513707 | M21: =(F21-F20)/F20 -> -0.004454343 | N21: =(G21-G20)/G20 -> 0.0074370709 | O21: =(H21-H20)/H20 -> 0.0045563748
A22: Rural+Urban | B22: 2022 | C22: September | D22: 2103.1 | E22: 169.5 | F22: 179.5 | G22: 355.2 | H22: 1217.1 | I22: 89.76 | J22: =(I22-I21)/I21 -> -0.10642111 | K22: =(D22-D21)/D21 -> 0.0048736203 | L22: =(E22-E21)/E21 -> 0.0029585799 | M22: =(F22-F21)/F21 -> 0.0039149888 | N22: =(G22-G21)/G21 -> 0.0085178876 | O22: =(H22-H21)/H21 -> 0.0037110341
A23: Rural+Urban | B23: 2022 | C23: October | D23: 2117.7 | E23: 171.2 | F23: 180.5 | G23: 357.2 | H23: 1222 | I23: 93.33 | J23: =(I23-I22)/I22 -> 0.039772727 | K23: =(D23-D22)/D22 -> 0.006942133 | L23: =(E23-E22)/E22 -> 0.010029499 | M23: =(F23-F22)/F22 -> 0.0055710306 | N23: =(G23-G22)/G22 -> 0.0056306306 | O23: =(H23-H22)/H22 -> 0.0040259634
... A30: Rural+Urban | B30: 2023 | C30: May | D30: 2127.8 | E30: 175.6 | F30: 182.8 | G30: 367 | H30: 1260.2 | I30: 75.47 | J30: =(I30-I29)/I29 -> -0.10834121 | K30: =(D30-D29)/D29 -> 0.007624189 | L30: =(E30-E29)/E29 -> 0.002283105 | M30: =(F30-F29)/F29 -> 0.0060539351 | N30: =(G30-G29)/G29 -> 0.0024583447 | O30: =(H30-H29)/H29 -> 0.0035037426
